Workbook
Name UPDATE: 'Data Sheet (2)'!$E$1
Name UPDATE: 'Data Sheet (3)'!$E$1
Name UPDATE: 'Data Sheet (2)'!$E$1
Name UPDATE: 'Data Sheet (3)'!$E$1
Name UPDATE: 'Data Sheet (2)'!$E$1
Name UPDATE: 'Data Sheet (3)'!$E$1
Name UPDATE: 'Data Sheet (2)'!$E$1
Name UPDATE: 'Data Sheet (3)'!$E$1
Name UPDATE: 'Data Sheet (2)'!$E$1
Name UPDATE: 'Data Sheet (3)'!$E$1
Name UPDATE: 'Data Sheet (2)'!$E$1
Name UPDATE: 'Data Sheet (3)'!$E$1
Name UPDATE: 'Data Sheet'!$E$1

Sheet Profit & Loss
A1: ='Data Sheet'!B1 -> BAJAJ FINSERV LTD | H1: =UPDATE | M1: SCREENER.IN
A3: Narration | B3: ='Data Sheet'!B16 -> 42825 | C3: ='Data Sheet'!C16 -> 43190 | D3: ='Data Sheet'!D16 -> 43555 | E3: ='Data Sheet'!E16 -> 43921 | F3: ='Data Sheet'!F16 -> 44286 | G3: ='Data Sheet'!G16 -> 44651 | H3: ='Data Sheet'!H16 -> 45016 | I3: ='Data Sheet'!I16 -> 45382 | ... K3: ='Data Sheet'!K16 -> 46112 | L3: Trailing | M3: Best Case | N3: Worst Case
A4: Sales | B4: ='Data Sheet'!B17 -> 24507.3 | C4: ='Data Sheet'!C17 -> 32862.46 | D4: ='Data Sheet'!D17 -> 42605.4 | E4: ='Data Sheet'!E17 -> 54351.37 | F4: ='Data Sheet'!F17 -> 60591.52 | G4: ='Data Sheet'!G17 -> 68406.28 | H4: ='Data Sheet'!H17 -> 82071.7 | I4: ='Data Sheet'!I17 -> 110382.29 | ... K4: ='Data Sheet'!K17 -> 150530.32 | L4: =SUM(Quarters!H4:K4) -> 157641.68 | M4: =$K4+M23*K4 -> 184261.32 | N4: =$K4+N23*L4 -> 171383.31
A5: Expenses | B5: =SUM('Data Sheet'!B18,'Data Sheet'!B20:B24, -1*'Data Sheet'!B19) -> 15794.02 | C5: =SUM('Data Sheet'!C18,'Data Sheet'!C20:C24, -1*'Data Sheet'!C19) -> 22074.35 | D5: =SUM('Data Sheet'!D18,'Data Sheet'!D20:D24, -1*'Data Sheet'!D19) -> 27568.7 | E5: =SUM('Data Sheet'!E18,'Data Sheet'!E20:E24, -1*'Data Sheet'!E19) -> 36093.67 | F5: =SUM('Data Sheet'!F18,'Data Sheet'!F20:F24, -1*'Data Sheet'!F19) -> 40950.23 | G5: =SUM('Data Sheet'!G18,'Data Sheet'!G20:G24, -1*'Data Sheet'!G19) -> 46951.37 | H5: =SUM('Data Sheet'!H18,'Data Sheet'!H20:H24, -1*'Data Sheet'!H19) -> 52203.97 | I5: =SUM('Data Sheet'!I18,'Data Sheet'!I20:I24, -1*'Data Sheet'!I19) -> 69496.74 | ... K5: =SUM('Data Sheet'!K18,'Data Sheet'!K20:K24, -1*'Data Sheet'!K19) -> 93432.6 | L5: =SUM(Quarters!H5:K5) -> 98073.55 | M5: =M4-M6 -> 114634.41 | N5: =N4-N6 -> 110151.19
A6: Operating Profit | B6: =B4-B5 -> 8713.28 | C6: =C4-C5 -> 10788.11 | D6: =D4-D5 -> 15036.7 | E6: =E4-E5 -> 18257.7 | F6: =F4-F5 -> 19641.29 | G6: =G4-G5 -> 21454.91 | H6: =H4-H5 -> 29867.73 | I6: =I4-I5 -> 40885.55 | ... K6: =K4-K5 -> 57097.72 | L6: =SUM(Quarters!H6:K6) -> 59568.13 | M6: =M4*M24 -> 69626.904 | N6: =N4*N24 -> 61232.121
A7: Other Income | B7: ='Data Sheet'!B25 -> 0.16 | C7: ='Data Sheet'!C25 -> 1.49 | D7: ='Data Sheet'!D25 -> 1.53 | E7: ='Data Sheet'!E25 -> 0.36 | F7: ='Data Sheet'!F25 -> -6.87 | G7: ='Data Sheet'!G25 -> 7.86 | H7: ='Data Sheet'!H25 -> 1.46 | I7: ='Data Sheet'!I25 -> -3.86 | ... K7: ='Data Sheet'!K25 -> -382.27 | L7: =SUM(Quarters!H7:K7) -> -344.19 | M7: 0 | N7: 0
A8: Depreciation | B8: ='Data Sheet'!B26 -> 72.63 | C8: ='Data Sheet'!C26 -> 159.89 | D8: ='Data Sheet'!D26 -> 226.09 | E8: ='Data Sheet'!E26 -> 456.79 | F8: ='Data Sheet'!F26 -> 498.46 | G8: ='Data Sheet'!G26 -> 562.73 | H8: ='Data Sheet'!H26 -> 677.8 | I8: ='Data Sheet'!I26 -> 900.13 | ... K8: ='Data Sheet'!K26 -> 1291.36 | L8: =SUM(Quarters!H8:K8) -> 1353.71 | M8: =+$L8 -> 1353.71 | N8: =+$L8 -> 1353.71
A9: Interest | B9: ='Data Sheet'!B27 -> 3716.28 | C9: ='Data Sheet'!C27 -> 4531 | D9: ='Data Sheet'!D27 -> 6657.4 | E9: ='Data Sheet'!E27 -> 9499.61 | F9: ='Data Sheet'!F27 -> 9273.62 | G9: ='Data Sheet'!G27 -> 9629.46 | H9: ='Data Sheet'!H27 -> 12380.26 | I9: ='Data Sheet'!I27 -> 18606.53 | ... K9: ='Data Sheet'!K27 -> 28540.94 | L9: =SUM(Quarters!H9:K9) -> 29258.53 | M9: =+$L9 -> 29258.53 | N9: =+$L9 -> 29258.53
A10: Profit before tax | B10: ='Data Sheet'!B28 -> 4924.53 | C10: ='Data Sheet'!C28 -> 6098.71 | D10: ='Data Sheet'!D28 -> 8154.74 | E10: ='Data Sheet'!E28 -> 8301.66 | F10: ='Data Sheet'!F28 -> 9862.34 | G10: ='Data Sheet'!G28 -> 11270.58 | H10: ='Data Sheet'!H28 -> 16811.13 | I10: ='Data Sheet'!I28 -> 21375.03 | ... K10: ='Data Sheet'!K28 -> 26883.15 | L10: =SUM(Quarters!H10:K10) -> 28611.7 | M10: =M6+M7-SUM(M8:M9) -> 39014.664 | N10: =N6+N7-SUM(N8:N9) -> 30619.881
A11: Tax | B11: ='Data Sheet'!B29 -> 1474.82 | C11: ='Data Sheet'!C29 -> 1922.36 | D11: ='Data Sheet'!D29 -> 2780.89 | E11: ='Data Sheet'!E29 -> 2308.06 | F11: ='Data Sheet'!F29 -> 2494.96 | G11: ='Data Sheet'!G29 -> 2957.05 | H11: ='Data Sheet'!H29 -> 4601.59 | I11: ='Data Sheet'!I29 -> 5779.67 | ... K11: ='Data Sheet'!K29 -> 7213.68 | L11: =SUM(Quarters!H11:K11) -> 7974.73 | M11: =IF($L10>0,$L11/$L10,0) -> 0.27872269 | N11: =IF($L10>0,$L11/$L10,0) -> 0.27872269
A12: Net profit | B12: ='Data Sheet'!B30 -> 2261.92 | C12: ='Data Sheet'!C30 -> 2650.26 | D12: ='Data Sheet'!D30 -> 3219.04 | E12: ='Data Sheet'!E30 -> 3369.13 | F12: ='Data Sheet'!F30 -> 4470.46 | G12: ='Data Sheet'!G30 -> 4556.77 | H12: ='Data Sheet'!H30 -> 6417.28 | I12: ='Data Sheet'!I30 -> 8147.79 | ... K12: ='Data Sheet'!K30 -> 9800.97 | L12: =SUM(Quarters!H12:K12) -> 10144.27 | M12: =M10-M11*M10 -> 28140.392 | N12: =N10-N11*N10 -> 22085.425
A13: EPS | B13: =IF('Data Sheet'!B93>0,B12/'Data Sheet'!B93,0) -> 14.212504 | C13: =IF('Data Sheet'!C93>0,C12/'Data Sheet'!C93,0) -> 16.652592 | D13: =IF('Data Sheet'!D93>0,D12/'Data Sheet'!D93,0) -> 20.226453 | E13: =IF('Data Sheet'!E93>0,E12/'Data Sheet'!E93,0) -> 21.169526 | F13: =IF('Data Sheet'!F93>0,F12/'Data Sheet'!F93,0) -> 28.089601 | G13: =IF('Data Sheet'!G93>0,G12/'Data Sheet'!G93,0) -> 28.63192 | H13: =IF('Data Sheet'!H93>0,H12/'Data Sheet'!H93,0) -> 40.289302 | I13: =IF('Data Sheet'!I93>0,I12/'Data Sheet'!I93,0) -> 51.067314 | ... K13: =IF('Data Sheet'!K93>0,K12/'Data Sheet'!K93,0) -> 61.2331 | L13: =IF('Data Sheet'!$B6>0,'Profit & Loss'!L12/'Data Sheet'!$B6,0) -> 63.429094 | M13: =IF('Data Sheet'!$B6>0,'Profit & Loss'!M12/'Data Sheet'!$B6,0) -> 175.95347 | N13: =IF('Data Sheet'!$B6>0,'Profit & Loss'!N12/'Data Sheet'!$B6,0) -> 138.09358
A14: Price to earning | B14: =IF(B15>0,B15/B13,"") -> 28.83658 | C14: =IF(C15>0,C15/C13,"") -> 31.055826 | D14: =IF(D15>0,D15/D13,"") -> 34.791567 | E14: =IF(E15>0,E15/E13,"") -> 21.687779 | F14: =IF(F15>0,F15/F13,"") -> 34.420567 | G14: =IF(G15>0,G15/G13,"") -> 59.585596 | H14: =IF(H15>0,H15/H13,"") -> 31.435144 | I14: =IF(I15>0,I15/I13,"") -> 32.189866 | ... K14: =IF(K15>0,K15/K13,"") -> 26.648986 | L14: =IF(L13>0,L15/L13,0) -> 29.20584 | M14: =M25 -> 31.042462 | N14: =N25 -> 29.20584
A15: Price | B15: ='Data Sheet'!B90 -> 409.84 | C15: ='Data Sheet'!C90 -> 517.16 | D15: ='Data Sheet'!D90 -> 703.71 | E15: ='Data Sheet'!E90 -> 459.12 | F15: ='Data Sheet'!F90 -> 966.86 | G15: ='Data Sheet'!G90 -> 1706.05 | H15: ='Data Sheet'!H90 -> 1266.5 | I15: ='Data Sheet'!I90 -> 1643.85 | ... K15: ='Data Sheet'!K90 -> 1631.8 | L15: ='Data Sheet'!B8 -> 1852.5 | M15: =M13*M14 -> 5462.029 | N15: =N13*N14 -> 4033.1389
A17: RATIOS:
A18: Dividend Payout | B18: =IF('Data Sheet'!B30>0, 'Data Sheet'!B31/'Data Sheet'!B30, 0) -> 0.012312549 | C18: =IF('Data Sheet'!C30>0, 'Data Sheet'!C31/'Data Sheet'!C30, 0) -> 0.010508403 | D18: =IF('Data Sheet'!D30>0, 'Data Sheet'!D31/'Data Sheet'!D30, 0) -> 0.012357722 | E18: =IF('Data Sheet'!E30>0, 'Data Sheet'!E31/'Data Sheet'!E30, 0) -> 0.023617373 | F18: =IF('Data Sheet'!F30>0, 'Data Sheet'!F31/'Data Sheet'!F30, 0) -> 0.010678991 | G18: =IF('Data Sheet'!G30>0, 'Data Sheet'!G31/'Data Sheet'!G30, 0) -> 0.013970422 | H18: =IF('Data Sheet'!H30>0, 'Data Sheet'!H31/'Data Sheet'!H30, 0) -> 0.019854206 | I18: =IF('Data Sheet'!I30>0, 'Data Sheet'!I31/'Data Sheet'!I30, 0) -> 0.019564815 | ... K18: =IF('Data Sheet'!K30>0, 'Data Sheet'!K31/'Data Sheet'!K30, 0) -> 0.024466966
A19: OPM | B19: =IF(B6>0,B6/B4,0) -> 0.35553815 | C19: =IF(C6>0,C6/C4,0) -> 0.32828066 | D19: =IF(D6>0,D6/D4,0) -> 0.35292944 | E19: =IF(E6>0,E6/E4,0) -> 0.33591978 | F19: =IF(F6>0,F6/F4,0) -> 0.32415906 | G19: =IF(G6>0,G6/G4,0) -> 0.31363948 | H19: =IF(H6>0,H6/H4,0) -> 0.3639224 | I19: =IF(I6>0,I6/I4,0) -> 0.37039955 | ... L19: =IF(L6>0,L6/L4,0) -> 0.37787043
G22: TRENDS: | H22: 10 YEARS | I22: 7 YEARS | J22: 5 YEARS | K22: 3 YEARS | L22: RECENT | M22: BEST | N22: WORST
G23: Sales Growth | H23: =IF(B4=0,"",POWER($K4/B4,1/9)-1) -> 0.22346643 | I23: =IF(D4=0,"",POWER($K4/D4,1/7)-1) -> 0.19759087 | J23: =IF(F4=0,"",POWER($K4/F4,1/5)-1) -> 0.19961649 | K23: =IF(H4=0,"",POWER($K4/H4, 1/3)-1) -> 0.22408108 | L23: =IF(ISERROR(MAX(IF(J4=0,"",(K4-J4)/J4),IF(K4=0,"",(L4-K4)/K4))),"",MAX(IF(J4=0,"",(K4-J4)/J4),IF(K4=0,"",(L4-K4)/K4))) -> 0.13228094 | M23: =MAX(K23:L23) -> 0.22408108 | N23: =MIN(H23:L23) -> 0.13228094
G24: OPM | H24: =IF(SUM(B4:$K$4)=0,"",SUMPRODUCT(B19:$K$19,B4:$K$4)/SUM(B4:$K$4)) -> 0.3572817 | I24: =IF(SUM(E4:$K$4)=0,"",SUMPRODUCT(E19:$K$19,E4:$K$4)/SUM(E4:$K$4)) -> 0.35907337 | J24: =IF(SUM(G4:$K$4)=0,"",SUMPRODUCT(G19:$K$19,G4:$K$4)/SUM(G4:$K$4)) -> 0.36527165 | K24: =IF(SUM(I4:$K$4)=0, "", SUMPRODUCT(I19:$K$19,I4:$K$4)/SUM(I4:$K$4)) -> 0.37452044 | L24: =L19 -> 0.37787043 | M24: =MAX(K24:L24) -> 0.37787043 | N24: =MIN(H24:L24) -> 0.3572817
G25: Price to Earning | H25: =IF(ISERROR(AVERAGEIF(B14:$L14,">0")),"",AVERAGEIF(B14:$L14,">0")) -> 33.271173 | I25: =IF(ISERROR(AVERAGEIF(E14:$L14,">0")),"",AVERAGEIF(E14:$L14,">0")) -> 33.912367 | J25: =IF(ISERROR(AVERAGEIF(G14:$L14,">0")),"",AVERAGEIF(G14:$L14,">0")) -> 35.865098 | K25: =IF(ISERROR(AVERAGEIF(I14:$L14,">0")),"",AVERAGEIF(I14:$L14,">0")) -> 31.042462 | L25: =L14 -> 29.20584 | M25: =MAX(K25:L25) -> 31.042462 | N25: =MIN(H25:L25) -> 29.20584

Sheet Quarters
A1: ='Profit & Loss'!A1 -> BAJAJ FINSERV LTD | E1: =UPDATE | J1: SCREENER.IN
A3: Narration | B3: ='Data Sheet'!B41 -> 45382 | C3: ='Data Sheet'!C41 -> 45473 | D3: ='Data Sheet'!D41 -> 45565 | E3: ='Data Sheet'!E41 -> 45657 | F3: ='Data Sheet'!F41 -> 45747 | G3: ='Data Sheet'!G41 -> 45838 | H3: ='Data Sheet'!H41 -> 45930 | I3: ='Data Sheet'!I41 -> 46022 | ... K3: ='Data Sheet'!K41 -> 46203
A4: Sales | B4: ='Data Sheet'!B42 -> 32040.84 | C4: ='Data Sheet'!C42 -> 31479.93 | D4: ='Data Sheet'!D42 -> 33703.74 | E4: ='Data Sheet'!E42 -> 32041.81 | F4: ='Data Sheet'!F42 -> 36595.36 | G4: ='Data Sheet'!G42 -> 35287.76 | H4: ='Data Sheet'!H42 -> 37402.93 | I4: ='Data Sheet'!I42 -> 39708.06 | ... K4: ='Data Sheet'!K42 -> 42036.9
A5: Expenses | B5: ='Data Sheet'!B43 -> 21108.3 | C5: ='Data Sheet'!C43 -> 19655.12 | D5: ='Data Sheet'!D43 -> 21420.27 | E5: ='Data Sheet'!E43 -> 19668.63 | F5: ='Data Sheet'!F43 -> 23867.86 | G5: ='Data Sheet'!G43 -> 20972.57 | H5: ='Data Sheet'!H43 -> 23352.48 | I5: ='Data Sheet'!I43 -> 25841.71 | ... K5: ='Data Sheet'!K43 -> 24896.29
A6: Operating Profit | B6: ='Data Sheet'!B50 -> 10932.54 | C6: ='Data Sheet'!C50 -> 11824.81 | D6: ='Data Sheet'!D50 -> 12283.47 | E6: ='Data Sheet'!E50 -> 12373.18 | F6: ='Data Sheet'!F50 -> 12727.5 | G6: ='Data Sheet'!G50 -> 14315.19 | H6: ='Data Sheet'!H50 -> 14050.45 | I6: ='Data Sheet'!I50 -> 13866.35 | ... K6: ='Data Sheet'!K50 -> 17140.61
A7: Other Income | B7: ='Data Sheet'!B44 -> 4.42 | C7: ='Data Sheet'!C44 -> 2.62 | D7: ='Data Sheet'!D44 -> 3.45 | E7: ='Data Sheet'!E44 -> 3.1 | F7: ='Data Sheet'!F44 -> 10.1 | G7: ='Data Sheet'!G44 -> 12.88 | H7: ='Data Sheet'!H44 -> 3.2 | I7: ='Data Sheet'!I44 -> -377.79 | ... K7: ='Data Sheet'!K44 -> 5.11
A8: Depreciation | B8: ='Data Sheet'!B45 -> 256.91 | C8: ='Data Sheet'!C45 -> 267.01 | D8: ='Data Sheet'!D45 -> 275.32 | E8: ='Data Sheet'!E45 -> 288.5 | F8: ='Data Sheet'!F45 -> 339.49 | G8: ='Data Sheet'!G45 -> 317.33 | H8: ='Data Sheet'!H45 -> 327.19 | I8: ='Data Sheet'!I45 -> 329.83 | ... K8: ='Data Sheet'!K45 -> 379.68
A9: Interest | B9: ='Data Sheet'!B46 -> 5153.51 | C9: ='Data Sheet'!C46 -> 5592.01 | D9: ='Data Sheet'!D46 -> 6045.63 | E9: ='Data Sheet'!E46 -> 6276.27 | F9: ='Data Sheet'!F46 -> 6395.79 | G9: ='Data Sheet'!G46 -> 6807.1 | H9: ='Data Sheet'!H46 -> 6901.33 | I9: ='Data Sheet'!I46 -> 7232.45 | ... K9: ='Data Sheet'!K46 -> 7833.85
A10: Profit before tax | B10: ='Data Sheet'!B47 -> 5526.54 | C10: ='Data Sheet'!C47 -> 5968.41 | D10: ='Data Sheet'!D47 -> 5965.97 | E10: ='Data Sheet'!E47 -> 5811.51 | F10: ='Data Sheet'!F47 -> 6002.32 | G10: ='Data Sheet'!G47 -> 7203.64 | H10: ='Data Sheet'!H47 -> 6825.13 | I10: ='Data Sheet'!I47 -> 5926.28 | ... K10: ='Data Sheet'!K47 -> 8932.19
A11: Tax | B11: ='Data Sheet'!B48 -> 1441.61 | C11: ='Data Sheet'!C48 -> 1759.13 | D11: ='Data Sheet'!D48 -> 1785.82 | E11: ='Data Sheet'!E48 -> 1399.62 | F11: ='Data Sheet'!F48 -> 1246 | G11: ='Data Sheet'!G48 -> 1874.47 | H11: ='Data Sheet'!H48 -> 2078.66 | I11: ='Data Sheet'!I48 -> 1558.71 | ... K11: ='Data Sheet'!K48 -> 2635.52
A12: Net profit | B12: ='Data Sheet'!B49 -> 2118.53 | C12: ='Data Sheet'!C49 -> 2137.7 | D12: ='Data Sheet'!D49 -> 2086.97 | E12: ='Data Sheet'!E49 -> 2231 | F12: ='Data Sheet'!F49 -> 2416.64 | G12: ='Data Sheet'!G49 -> 2789.05 | H12: ='Data Sheet'!H49 -> 2244.1 | I12: ='Data Sheet'!I49 -> 2229.15 | ... K12: ='Data Sheet'!K49 -> 3132.35
A14: OPM | B14: =IF(B4>0,B6/B4,"") -> 0.34120641 | C14: =IF(C4>0,C6/C4,"") -> 0.37563012 | D14: =IF(D4>0,D6/D4,"") -> 0.36445421 | E14: =IF(E4>0,E6/E4,"") -> 0.38615734 | F14: =IF(F4>0,F6/F4,"") -> 0.34778999 | G14: =IF(G4>0,G6/G4,"") -> 0.40567012 | H14: =IF(H4>0,H6/H4,"") -> 0.37565105 | I14: =IF(I4>0,I6/I4,"") -> 0.34920744 | ... K14: =IF(K4>0,K6/K4,"") -> 0.40775152

Sheet Balance Sheet
A1: ='Profit & Loss'!A1 -> BAJAJ FINSERV LTD | E1: =UPDATE | J1: SCREENER.IN
A3: Narration | B3: ='Data Sheet'!B56 -> 42825 | C3: ='Data Sheet'!C56 -> 43190 | D3: ='Data Sheet'!D56 -> 43555 | E3: ='Data Sheet'!E56 -> 43921 | F3: ='Data Sheet'!F56 -> 44286 | G3: ='Data Sheet'!G56 -> 44651 | H3: ='Data Sheet'!H56 -> 45016 | I3: ='Data Sheet'!I56 -> 45382 | ... K3: ='Data Sheet'!K56 -> 46112
A4: Equity Share Capital | B4: ='Data Sheet'!B57 -> 79.57 | C4: ='Data Sheet'!C57 -> 79.57 | D4: ='Data Sheet'!D57 -> 79.57 | E4: ='Data Sheet'!E57 -> 79.57 | F4: ='Data Sheet'!F57 -> 79.57 | G4: ='Data Sheet'!G57 -> 79.57 | H4: ='Data Sheet'!H57 -> 159.26 | I4: ='Data Sheet'!I57 -> 159.41 | ... K4: ='Data Sheet'!K57 -> 159.87
A5: Reserves | B5: ='Data Sheet'!B58 -> 16070.76 | C5: ='Data Sheet'!C58 -> 20403.37 | D5: ='Data Sheet'!D58 -> 23660.5 | E5: ='Data Sheet'!E58 -> 31221.68 | F5: ='Data Sheet'!F58 -> 35750.43 | G5: ='Data Sheet'!G58 -> 40167.23 | H5: ='Data Sheet'!H58 -> 46248.08 | I5: ='Data Sheet'!I58 -> 60169.23 | ... K5: ='Data Sheet'!K58 -> 77754.66
A6: Borrowings | B6: ='Data Sheet'!B59 -> 48282.04 | C6: ='Data Sheet'!C59 -> 65694.72 | D6: ='Data Sheet'!D59 -> 99754.35 | E6: ='Data Sheet'!E59 -> 127212.03 | F6: ='Data Sheet'!F59 -> 128460.85 | G6: ='Data Sheet'!G59 -> 161179.18 | H6: ='Data Sheet'!H59 -> 212264.97 | I6: ='Data Sheet'!I59 -> 288932.62 | ... K6: ='Data Sheet'!K59 -> 429913.96
A7: Other Liabilities | B7: ='Data Sheet'!B60 -> 64181.29 | C7: ='Data Sheet'!C60 -> 75336.6 | D7: ='Data Sheet'!D60 -> 84933.76 | E7: ='Data Sheet'!E60 -> 92790.87 | F7: ='Data Sheet'!F60 -> 115553.86 | G7: ='Data Sheet'!G60 -> 131987.23 | H7: ='Data Sheet'!H60 -> 146728.84 | I7: ='Data Sheet'!I60 -> 188153.88 | ... K7: ='Data Sheet'!K60 -> 250666.25
A8: Total | B8: ='Data Sheet'!B61 -> 128613.66 | C8: ='Data Sheet'!C61 -> 161514.26 | D8: ='Data Sheet'!D61 -> 208428.18 | E8: ='Data Sheet'!E61 -> 251304.15 | F8: ='Data Sheet'!F61 -> 279844.71 | G8: ='Data Sheet'!G61 -> 333413.21 | H8: ='Data Sheet'!H61 -> 405401.15 | I8: ='Data Sheet'!I61 -> 537415.14 | ... K8: ='Data Sheet'!K61 -> 758494.74
A10: Net Block | B10: ='Data Sheet'!B62 -> 1645.4 | C10: ='Data Sheet'!C62 -> 1791.85 | D10: ='Data Sheet'!D62 -> 2096.83 | E10: ='Data Sheet'!E62 -> 3215.62 | F10: ='Data Sheet'!F62 -> 3182.1 | G10: ='Data Sheet'!G62 -> 3585.58 | H10: ='Data Sheet'!H62 -> 4336.01 | I10: ='Data Sheet'!I62 -> 5455.34 | ... K10: ='Data Sheet'!K62 -> 6729.07
A11: Capital Work in Progress | B11: ='Data Sheet'!B63 -> 3.54 | C11: ='Data Sheet'!C63 -> 27.7 | D11: ='Data Sheet'!D63 -> 65.51 | E11: ='Data Sheet'!E63 -> 44.69 | F11: ='Data Sheet'!F63 -> 128.85 | G11: ='Data Sheet'!G63 -> 112.81 | H11: ='Data Sheet'!H63 -> 191.27 | I11: ='Data Sheet'!I63 -> 220.08 | ... K11: ='Data Sheet'!K63 -> 321.31
A12: Investments | B12: ='Data Sheet'!B64 -> 62658.46 | C12: ='Data Sheet'!C64 -> 69428.48 | D12: ='Data Sheet'!D64 -> 81679.06 | E12: ='Data Sheet'!E64 -> 91821.05 | F12: ='Data Sheet'!F64 -> 113654.41 | G12: ='Data Sheet'!G64 -> 119222.08 | H12: ='Data Sheet'!H64 -> 136175.73 | I12: ='Data Sheet'!I64 -> 170126.84 | ... K12: ='Data Sheet'!K64 -> 194413.54
A13: Other Assets | B13: ='Data Sheet'!B65 -> 64306.26 | C13: ='Data Sheet'!C65 -> 90266.23 | D13: ='Data Sheet'!D65 -> 124586.78 | E13: ='Data Sheet'!E65 -> 156222.79 | F13: ='Data Sheet'!F65 -> 162879.35 | G13: ='Data Sheet'!G65 -> 210492.74 | H13: ='Data Sheet'!H65 -> 264698.14 | I13: ='Data Sheet'!I65 -> 361612.88 | ... K13: ='Data Sheet'!K65 -> 557030.82
A14: Total | B14: ='Data Sheet'!B66 -> 128613.66 | C14: ='Data Sheet'!C66 -> 161514.26 | D14: ='Data Sheet'!D66 -> 208428.18 | E14: ='Data Sheet'!E66 -> 251304.15 | F14: ='Data Sheet'!F66 -> 279844.71 | G14: ='Data Sheet'!G66 -> 333413.21 | H14: ='Data Sheet'!H66 -> 405401.15 | I14: ='Data Sheet'!I66 -> 537415.14 | ... K14: ='Data Sheet'!K66 -> 758494.74
A16: Working Capital | B16: =B13-B7 -> 124.97 | C16: =C13-C7 -> 14929.63 | D16: =D13-D7 -> 39653.02 | E16: =E13-E7 -> 63431.92 | F16: =F13-F7 -> 47325.49 | G16: =G13-G7 -> 78505.51 | H16: =H13-H7 -> 117969.3 | I16: =I13-I7 -> 173459 | ... K16: =K13-K7 -> 306364.57
A17: Debtors | B17: ='Data Sheet'!B67 -> 1253.12 | C17: ='Data Sheet'!C67 -> 1753.28 | D17: ='Data Sheet'!D67 -> 2273.08 | E17: ='Data Sheet'!E67 -> 2657.81 | F17: ='Data Sheet'!F67 -> 2753.07 | G17: ='Data Sheet'!G67 -> 3004.81 | H17: ='Data Sheet'!H67 -> 3458.64 | I17: ='Data Sheet'!I67 -> 5973.86 | ... K17: ='Data Sheet'!K67 -> 9332.08
A18: Inventory | B18: ='Data Sheet'!B68 -> 0 | C18: ='Data Sheet'!C68 -> 0 | D18: ='Data Sheet'!D68 -> 0 | E18: ='Data Sheet'!E68 -> 0 | F18: ='Data Sheet'!F68 -> 0 | G18: ='Data Sheet'!G68 -> 0 | H18: ='Data Sheet'!H68 -> 0 | I18: ='Data Sheet'!I68 -> 0 | ... K18: ='Data Sheet'!K68 -> 0
A20: Debtor Days | B20: =IF('Profit & Loss'!B4>0,'Balance Sheet'!B17/('Profit & Loss'!B4/365),0) -> 18.66337 | C20: =IF('Profit & Loss'!C4>0,'Balance Sheet'!C17/('Profit & Loss'!C4/365),0) -> 19.473503 | D20: =IF('Profit & Loss'!D4>0,'Balance Sheet'!D17/('Profit & Loss'!D4/365),0) -> 19.473452 | E20: =IF('Profit & Loss'!E4>0,'Balance Sheet'!E17/('Profit & Loss'!E4/365),0) -> 17.848688 | F20: =IF('Profit & Loss'!F4>0,'Balance Sheet'!F17/('Profit & Loss'!F4/365),0) -> 16.584343 | G20: =IF('Profit & Loss'!G4>0,'Balance Sheet'!G17/('Profit & Loss'!G4/365),0) -> 16.032967 | H20: =IF('Profit & Loss'!H4>0,'Balance Sheet'!H17/('Profit & Loss'!H4/365),0) -> 15.381716 | I20: =IF('Profit & Loss'!I4>0,'Balance Sheet'!I17/('Profit & Loss'!I4/365),0) -> 19.753702 | ... K20: =IF('Profit & Loss'!K4>0,'Balance Sheet'!K17/('Profit & Loss'!K4/365),0) -> 22.628061
A21: Inventory Turnover | B21: =IF('Balance Sheet'!B18>0,'Profit & Loss'!B4/'Balance Sheet'!B18,0) -> 0 | C21: =IF('Balance Sheet'!C18>0,'Profit & Loss'!C4/'Balance Sheet'!C18,0) -> 0 | D21: =IF('Balance Sheet'!D18>0,'Profit & Loss'!D4/'Balance Sheet'!D18,0) -> 0 | E21: =IF('Balance Sheet'!E18>0,'Profit & Loss'!E4/'Balance Sheet'!E18,0) -> 0 | F21: =IF('Balance Sheet'!F18>0,'Profit & Loss'!F4/'Balance Sheet'!F18,0) -> 0 | G21: =IF('Balance Sheet'!G18>0,'Profit & Loss'!G4/'Balance Sheet'!G18,0) -> 0 | H21: =IF('Balance Sheet'!H18>0,'Profit & Loss'!H4/'Balance Sheet'!H18,0) -> 0 | I21: =IF('Balance Sheet'!I18>0,'Profit & Loss'!I4/'Balance Sheet'!I18,0) -> 0 | ... K21: =IF('Balance Sheet'!K18>0,'Profit & Loss'!K4/'Balance Sheet'!K18,0) -> 0
A23: Return on Equity | B23: =IF(SUM('Balance Sheet'!B4:B5)>0,'Profit & Loss'!B12/SUM('Balance Sheet'!B4:B5),"") -> 0.1400541 | C23: =IF(SUM('Balance Sheet'!C4:C5)>0,'Profit & Loss'!C12/SUM('Balance Sheet'!C4:C5),"") -> 0.12938865 | D23: =IF(SUM('Balance Sheet'!D4:D5)>0,'Profit & Loss'!D12/SUM('Balance Sheet'!D4:D5),"") -> 0.13559522 | E23: =IF(SUM('Balance Sheet'!E4:E5)>0,'Profit & Loss'!E12/SUM('Balance Sheet'!E4:E5),"") -> 0.10763564 | F23: =IF(SUM('Balance Sheet'!F4:F5)>0,'Profit & Loss'!F12/SUM('Balance Sheet'!F4:F5),"") -> 0.12476863 | G23: =IF(SUM('Balance Sheet'!G4:G5)>0,'Profit & Loss'!G12/SUM('Balance Sheet'!G4:G5),"") -> 0.11322068 | H23: =IF(SUM('Balance Sheet'!H4:H5)>0,'Profit & Loss'!H12/SUM('Balance Sheet'!H4:H5),"") -> 0.13828157 | I23: =IF(SUM('Balance Sheet'!I4:I5)>0,'Profit & Loss'!I12/SUM('Balance Sheet'!I4:I5),"") -> 0.13505675 | ... K23: =IF(SUM('Balance Sheet'!K4:K5)>0,'Profit & Loss'!K12/SUM('Balance Sheet'!K4:K5),"") -> 0.1257913
A24: Return on Capital Emp | C24: =IF((B4+B5+B6+C4+C5+C6)>0,('Profit & Loss'!C10+'Profit & Loss'!C9)*2/(B4+B5+B6+C4+C5+C6),"") -> 0.14115541 | D24: =IF((C4+C5+C6+D4+D5+D6)>0,('Profit & Loss'!D10+'Profit & Loss'!D9)*2/(C4+C5+C6+D4+D5+D6),"") -> 0.14128863 | E24: =IF((D4+D5+D6+E4+E5+E6)>0,('Profit & Loss'!E10+'Profit & Loss'!E9)*2/(D4+D5+D6+E4+E5+E6),"") -> 0.12624669 | F24: =IF((E4+E5+E6+F4+F5+F6)>0,('Profit & Loss'!F10+'Profit & Loss'!F9)*2/(E4+E5+E6+F4+F5+F6),"") -> 0.11856081 | G24: =IF((F4+F5+F6+G4+G5+G6)>0,('Profit & Loss'!G10+'Profit & Loss'!G9)*2/(F4+F5+F6+G4+G5+G6),"") -> 0.1142963 | H24: =IF((G4+G5+G6+H4+H5+H6)>0,('Profit & Loss'!H10+'Profit & Loss'!H9)*2/(G4+G5+G6+H4+H5+H6),"") -> 0.12689197 | I24: =IF((H4+H5+H6+I4+I5+I6)>0,('Profit & Loss'!I10+'Profit & Loss'!I9)*2/(H4+H5+H6+I4+I5+I6),"") -> 0.13153266 | J24: =IF((I4+I5+I6+J4+J5+J6)>0,('Profit & Loss'!J10+'Profit & Loss'!J9)*2/(I4+I5+I6+J4+J5+J6),"") -> 0.12433397 | K24: =IF((J4+J5+J6+K4+K5+K6)>0,('Profit & Loss'!K10+'Profit & Loss'!K9)*2/(J4+J5+J6+K4+K5+K6),"") -> 0.11841762

Sheet Customization
A1: How to use it?
A3: You can customize this workbook as you want.
B4: You can add custom formating, add conditional formating, add your own formulas… do ANYTHING.
B5: Please don't edit the "Data Sheet" only.
A7: After customization, you can upload this back on Screener.
B8: Upload on: | C8: https://www.screener.in/excel/
A10: Download your customized workbooks now onwards.
B11: Now whenever you will "Export to excel" from Screener, it will export your customized file.
A14: TESTING:
B15: This is a testing feature currently.
B16: You can report any formula errors on the worksheet at: support@screener.in

Sheet Data Sheet
A1: COMPANY NAME | B1: BAJAJ FINSERV LTD | E1: =IF(B2<>B3, "A NEW VERSION OF THE WORKSHEET IS AVAILABLE", "")
A2: LATEST VERSION | B2: 2.1 | E2: PLEASE DO NOT MAKE ANY CHANGES TO THIS SHEET
A3: CURRENT VERSION | B3: 2.1
A5: META
A6: Number of shares | B6: =IF(B9>0, B9/B8, 0) -> 159.93087
A7: Face Value | B7: 1
A8: Current Price | B8: 1852.5
A9: Market Capitalization | B9: 296271.93
A15: PROFIT & LOSS
A16: Report Date | B16: 42825 | C16: 43190 | D16: 43555 | E16: 43921 | F16: 44286 | G16: 44651 | H16: 45016 | I16: 45382 | J16: 45747 | K16: 46112
A17: Sales | B17: 24507.3 | C17: 32862.46 | D17: 42605.4 | E17: 54351.37 | F17: 60591.52 | G17: 68406.28 | H17: 82071.7 | I17: 110382.29 | J17: 132944.32 | K17: 150530.32
A18: Raw Material Cost
A19: Change in Inventory
A20: Power and Fuel | D20: 40.9 | E20: 9.6 | F20: 9.08 | G20: 5.31 | H20: 0.32 | I20: 0.11 | J20: 0.29 | K20: 0.15
A21: Other Mfr. Exp | B21: 27.13 | C21: 1400.74 | D21: 19290.57 | E21: 23739.27 | F21: 27447.36 | G21: 31698.37 | H21: 34692.78 | I21: 48840.32 | J21: 58017.39 | K21: 62951.89
A22: Employee Cost | B22: 1003.97 | C22: 2749.4 | D22: 3807.61 | E22: 4763.12 | F22: 4704.41 | G22: 6567.43 | H22: 8775.51 | I22: 10380.16 | J22: 12094.51 | K22: 14152.53
A23: Selling and admin | B23: 661.03 | C23: 1822.37 | D23: 2125.92 | E23: 2841.03 | F23: 2381.91 | G23: 3322.4 | H23: 4848.28 | I23: 4583.79 | J23: 5297.7 | K23: 5708.91
A24: Other Expenses | B24: 14101.89 | C24: 16101.84 | D24: 2303.7 | E24: 4740.65 | F24: 6407.47 | G24: 5357.86 | H24: 3887.08 | I24: 5692.36 | J24: 8010.23 | K24: 10619.12
A25: Other Income | B25: 0.16 | C25: 1.49 | D25: 1.53 | E25: 0.36 | F25: -6.87 | G25: 7.86 | H25: 1.46 | I25: -3.86 | J25: -18.35 | K25: -382.27
A26: Depreciation | B26: 72.63 | C26: 159.89 | D26: 226.09 | E26: 456.79 | F26: 498.46 | G26: 562.73 | H26: 677.8 | I26: 900.13 | J26: 1170.32 | K26: 1291.36
A27: Interest | B27: 3716.28 | C27: 4531 | D27: 6657.4 | E27: 9499.61 | F27: 9273.62 | G27: 9629.46 | H27: 12380.26 | I27: 18606.53 | J27: 24587.32 | K27: 28540.94
A28: Profit before tax | B28: 4924.53 | C28: 6098.71 | D28: 8154.74 | E28: 8301.66 | F28: 9862.34 | G28: 11270.58 | H28: 16811.13 | I28: 21375.03 | J28: 23748.21 | K28: 26883.15
A29: Tax | B29: 1474.82 | C29: 1922.36 | D29: 2780.89 | E29: 2308.06 | F29: 2494.96 | G29: 2957.05 | H29: 4601.59 | I29: 5779.67 | J29: 6190.57 | K29: 7213.68
A30: Net profit | B30: 2261.92 | C30: 2650.26 | D30: 3219.04 | E30: 3369.13 | F30: 4470.46 | G30: 4556.77 | H30: 6417.28 | I30: 8147.79 | J30: 8872.31 | K30: 9800.97
A31: Dividend Amount | B31: 27.85 | C31: 27.85 | D31: 39.78 | E31: 79.57 | F31: 47.74 | G31: 63.66 | H31: 127.41 | I31: 159.41 | J31: 159.6 | K31: 239.8
A40: Quarters
A41: Report Date | B41: 45382 | C41: 45473 | D41: 45565 | E41: 45657 | F41: 45747 | G41: 45838 | H41: 45930 | I41: 46022 | J41: 46112 | K41: 46203
A42: Sales | B42: 32040.84 | C42: 31479.93 | D42: 33703.74 | E42: 32041.81 | F42: 36595.36 | G42: 35287.76 | H42: 37402.93 | I42: 39708.06 | J42: 38493.79 | K42: 42036.9
A43: Expenses | B43: 21108.3 | C43: 19655.12 | D43: 21420.27 | E43: 19668.63 | F43: 23867.86 | G43: 20972.57 | H43: 23352.48 | I43: 25841.71 | J43: 23983.07 | K43: 24896.29
A44: Other Income | B44: 4.42 | C44: 2.62 | D44: 3.45 | E44: 3.1 | F44: 10.1 | G44: 12.88 | H44: 3.2 | I44: -377.79 | J44: 25.29 | K44: 5.11
A45: Depreciation | B45: 256.91 | C45: 267.01 | D45: 275.32 | E45: 288.5 | F45: 339.49 | G45: 317.33 | H45: 327.19 | I45: 329.83 | J45: 317.01 | K45: 379.68
A46: Interest | B46: 5153.51 | C46: 5592.01 | D46: 6045.63 | E46: 6276.27 | F46: 6395.79 | G46: 6807.1 | H46: 6901.33 | I46: 7232.45 | J46: 7290.9 | K46: 7833.85
A47: Profit before tax | B47: 5526.54 | C47: 5968.41 | D47: 5965.97 | E47: 5811.51 | F47: 6002.32 | G47: 7203.64 | H47: 6825.13 | I47: 5926.28 | J47: 6928.1 | K47: 8932.19
A48: Tax | B48: 1441.61 | C48: 1759.13 | D48: 1785.82 | E48: 1399.62 | F48: 1246 | G48: 1874.47 | H48: 2078.66 | I48: 1558.71 | J48: 1701.84 | K48: 2635.52
A49: Net profit | B49: 2118.53 | C49: 2137.7 | D49: 2086.97 | E49: 2231 | F49: 2416.64 | G49: 2789.05 | H49: 2244.1 | I49: 2229.15 | J49: 2538.67 | K49: 3132.35
A50: Operating Profit | B50: 10932.54 | C50: 11824.81 | D50: 12283.47 | E50: 12373.18 | F50: 12727.5 | G50: 14315.19 | H50: 14050.45 | I50: 13866.35 | J50: 14510.72 | K50: 17140.61
A55: BALANCE SHEET
A56: Report Date | B56: 42825 | C56: 43190 | D56: 43555 | E56: 43921 | F56: 44286 | G56: 44651 | H56: 45016 | I56: 45382 | J56: 45747 | K56: 46112
A57: Equity Share Capital | B57: 79.57 | C57: 79.57 | D57: 79.57 | E57: 79.57 | F57: 79.57 | G57: 79.57 | H57: 159.26 | I57: 159.41 | J57: 159.6 | K57: 159.87
A58: Reserves | B58: 16070.76 | C58: 20403.37 | D58: 23660.5 | E58: 31221.68 | F58: 35750.43 | G58: 40167.23 | H58: 46248.08 | I58: 60169.23 | J58: 72235.71 | K58: 77754.66
...

Sheet Cash Flow
A1: ='Balance Sheet'!A1 -> BAJAJ FINSERV LTD | E1: =UPDATE | J1: SCREENER.IN
A3: Narration | B3: ='Data Sheet'!B81 -> 42825 | C3: ='Data Sheet'!C81 -> 43190 | D3: ='Data Sheet'!D81 -> 43555 | E3: ='Data Sheet'!E81 -> 43921 | F3: ='Data Sheet'!F81 -> 44286 | G3: ='Data Sheet'!G81 -> 44651 | H3: ='Data Sheet'!H81 -> 45016 | I3: ='Data Sheet'!I81 -> 45382 | ... K3: ='Data Sheet'!K81 -> 46112
A4: Cash from Operating Activity | B4: ='Data Sheet'!B82 -> -10922.24 | C4: ='Data Sheet'!C82 -> -19580.16 | D4: ='Data Sheet'!D82 -> -27076.37 | E4: ='Data Sheet'!E82 -> -23369.03 | F4: ='Data Sheet'!F82 -> 4547.4 | G4: ='Data Sheet'!G82 -> -33669.99 | H4: ='Data Sheet'!H82 -> -39479.54 | I4: ='Data Sheet'!I82 -> -65502.04 | ... K4: ='Data Sheet'!K82 -> -55301.41
A5: Cash from Investing Activity | B5: ='Data Sheet'!B83 -> 151.3 | C5: ='Data Sheet'!C83 -> -921.5 | D5: ='Data Sheet'!D83 -> -6903.41 | E5: ='Data Sheet'!E83 -> -9948 | F5: ='Data Sheet'!F83 -> -3683.8 | G5: ='Data Sheet'!G83 -> 1445.43 | H5: ='Data Sheet'!H83 -> -13945.21 | I5: ='Data Sheet'!I83 -> -14131.71 | ... K5: ='Data Sheet'!K83 -> -12634.87
A6: Cash from Financing Activity | B6: ='Data Sheet'!B84 -> 12512.74 | C6: ='Data Sheet'!C84 -> 19590.17 | D6: ='Data Sheet'!D84 -> 34534.82 | E6: ='Data Sheet'!E84 -> 34479.35 | F6: ='Data Sheet'!F84 -> 1686.95 | G6: ='Data Sheet'!G84 -> 32325.76 | H6: ='Data Sheet'!H84 -> 51016.06 | I6: ='Data Sheet'!I84 -> 82708.61 | ... K6: ='Data Sheet'!K84 -> 66610.32
A7: Net Cash Flow | B7: ='Data Sheet'!B85 -> 1741.8 | C7: ='Data Sheet'!C85 -> -911.49 | D7: ='Data Sheet'!D85 -> 555.04 | E7: ='Data Sheet'!E85 -> 1162.32 | F7: ='Data Sheet'!F85 -> 2550.55 | G7: ='Data Sheet'!G85 -> 101.2 | H7: ='Data Sheet'!H85 -> -2408.69 | I7: ='Data Sheet'!I85 -> 3074.86 | ... K7: ='Data Sheet'!K85 -> -1325.96

Sheet Profit & Loss (2)
A1: ='Data Sheet (2)'!B1 -> L&T FINANCE LTD | H1: =UPDATE | M1: SCREENER.IN
A3: Narration | B3: ='Data Sheet (2)'!B16 -> 42825 | C3: ='Data Sheet (2)'!C16 -> 43190 | D3: ='Data Sheet (2)'!D16 -> 43555 | E3: ='Data Sheet (2)'!E16 -> 43921 | F3: ='Data Sheet (2)'!F16 -> 44286 | G3: ='Data Sheet (2)'!G16 -> 44651 | H3: ='Data Sheet (2)'!H16 -> 45016 | I3: ='Data Sheet (2)'!I16 -> 45382 | ... K3: ='Data Sheet (2)'!K16 -> 46112 | L3: Trailing | M3: Best Case | N3: Worst Case
A4: Sales | B4: ='Data Sheet (2)'!B17 -> 8531.58 | C4: ='Data Sheet (2)'!C17 -> 10214.55 | D4: ='Data Sheet (2)'!D17 -> 13364.93 | E4: ='Data Sheet (2)'!E17 -> 14104.12 | F4: ='Data Sheet (2)'!F17 -> 13352.85 | G4: ='Data Sheet (2)'!G17 -> 11929.7 | H4: ='Data Sheet (2)'!H17 -> 12774.95 | I4: ='Data Sheet (2)'!I17 -> 14251.71 | ... K4: ='Data Sheet (2)'!K17 -> 17913.67 | L4: =SUM('Quarters (2)'!H4:K4) -> 18897.97 | M4: =$K4+M23*K4 -> 20151.641 | N4: =$K4+N23*L4 -> 18721.276
A5: Expenses | B5: =SUM('Data Sheet (2)'!B18,'Data Sheet (2)'!B20:B24, -1*'Data Sheet (2)'!B19) -> 2775.95 | C5: =SUM('Data Sheet (2)'!C18,'Data Sheet (2)'!C20:C24, -1*'Data Sheet (2)'!C19) -> 3307.81 | D5: =SUM('Data Sheet (2)'!D18,'Data Sheet (2)'!D20:D24, -1*'Data Sheet (2)'!D19) -> 3377.32 | E5: =SUM('Data Sheet (2)'!E18,'Data Sheet (2)'!E20:E24, -1*'Data Sheet (2)'!E19) -> 4160.17 | F5: =SUM('Data Sheet (2)'!F18,'Data Sheet (2)'!F20:F24, -1*'Data Sheet (2)'!F19) -> 5401.17 | G5: =SUM('Data Sheet (2)'!G18,'Data Sheet (2)'!G20:G24, -1*'Data Sheet (2)'!G19) -> 5233.05 | H5: =SUM('Data Sheet (2)'!H18,'Data Sheet (2)'!H20:H24, -1*'Data Sheet (2)'!H19) -> 7935.31 | I5: =SUM('Data Sheet (2)'!I18,'Data Sheet (2)'!I20:I24, -1*'Data Sheet (2)'!I19) -> 6195.16 | ... K5: =SUM('Data Sheet (2)'!K18,'Data Sheet (2)'!K20:K24, -1*'Data Sheet (2)'!K19) -> 6945.83 | L5: =SUM('Quarters (2)'!H5:K5) -> 7325.86 | M5: =M4-M6 -> 7811.8498 | N5: =N4-N6 -> 8387.4344
A6: Operating Profit | B6: =B4-B5 -> 5755.63 | C6: =C4-C5 -> 6906.74 | D6: =D4-D5 -> 9987.61 | E6: =E4-E5 -> 9943.95 | F6: =F4-F5 -> 7951.68 | G6: =G4-G5 -> 6696.65 | H6: =H4-H5 -> 4839.64 | I6: =I4-I5 -> 8056.55 | ... K6: =K4-K5 -> 10967.84 | L6: =SUM('Quarters (2)'!H6:K6) -> 11572.11 | M6: =M4*M24 -> 12339.792 | N6: =N4*N24 -> 10333.842
A7: Other Income | B7: ='Data Sheet (2)'!B25 -> 25.93 | C7: ='Data Sheet (2)'!C25 -> 48.7 | D7: ='Data Sheet (2)'!D25 -> -3.73 | E7: ='Data Sheet (2)'!E25 -> 369.96 | F7: ='Data Sheet (2)'!F25 -> 836.12 | G7: ='Data Sheet (2)'!G25 -> 593.86 | H7: ='Data Sheet (2)'!H25 -> 2792.12 | I7: ='Data Sheet (2)'!I25 -> 473.91 | ... K7: ='Data Sheet (2)'!K25 -> -26.16 | L7: =SUM('Quarters (2)'!H7:K7) -> 5.21 | M7: 0 | N7: 0
A8: Depreciation | B8: ='Data Sheet (2)'!B26 -> 67.3 | C8: ='Data Sheet (2)'!C26 -> 51.93 | D8: ='Data Sheet (2)'!D26 -> 49.62 | E8: ='Data Sheet (2)'!E26 -> 81.59 | F8: ='Data Sheet (2)'!F26 -> 85.66 | G8: ='Data Sheet (2)'!G26 -> 102.64 | H8: ='Data Sheet (2)'!H26 -> 111.24 | I8: ='Data Sheet (2)'!I26 -> 114.77 | ... K8: ='Data Sheet (2)'!K26 -> 209.69 | L8: =SUM('Quarters (2)'!H8:K8) -> 231.68 | M8: =+$L8 -> 231.68 | N8: =+$L8 -> 231.68
A9: Interest | B9: ='Data Sheet (2)'!B27 -> 4635.36 | C9: ='Data Sheet (2)'!C27 -> 5457.75 | D9: ='Data Sheet (2)'!D27 -> 6882.28 | E9: ='Data Sheet (2)'!E27 -> 7552.24 | F9: ='Data Sheet (2)'!F27 -> 7230.15 | G9: ='Data Sheet (2)'!G27 -> 5765.01 | H9: ='Data Sheet (2)'!H27 -> 5811.67 | I9: ='Data Sheet (2)'!I27 -> 5386.66 | ... K9: ='Data Sheet (2)'!K27 -> 6733.82 | L9: =SUM('Quarters (2)'!H9:K9) -> 7054.41 | M9: =+$L9 -> 7054.41 | N9: =+$L9 -> 7054.41
A10: Profit before tax | B10: ='Data Sheet (2)'!B28 -> 1078.9 | C10: ='Data Sheet (2)'!C28 -> 1445.76 | D10: ='Data Sheet (2)'!D28 -> 3051.98 | E10: ='Data Sheet (2)'!E28 -> 2680.08 | F10: ='Data Sheet (2)'!F28 -> 1471.99 | G10: ='Data Sheet (2)'!G28 -> 1422.86 | H10: ='Data Sheet (2)'!H28 -> 1708.85 | I10: ='Data Sheet (2)'!I28 -> 3029.03 | ... K10: ='Data Sheet (2)'!K28 -> 3998.17 | L10: =SUM('Quarters (2)'!H10:K10) -> 4291.23 | M10: =M6+M7-SUM(M8:M9) -> 5053.7015 | N10: =N6+N7-SUM(N8:N9) -> 3047.7517
A11: Tax | B11: ='Data Sheet (2)'!B29 -> 36.44 | C11: ='Data Sheet (2)'!C29 -> 168.24 | D11: ='Data Sheet (2)'!D29 -> 819.95 | E11: ='Data Sheet (2)'!E29 -> 979.82 | F11: ='Data Sheet (2)'!F29 -> 523.11 | G11: ='Data Sheet (2)'!G29 -> 373.62 | H11: ='Data Sheet (2)'!H29 -> 172.37 | I11: ='Data Sheet (2)'!I29 -> 711.9 | ... K11: ='Data Sheet (2)'!K29 -> 1015.3 | L11: =SUM('Quarters (2)'!H11:K11) -> 1093.21 | M11: =IF($L10>0,$L11/$L10,0) -> 0.25475446 | N11: =IF($L10>0,$L11/$L10,0) -> 0.25475446
A12: Net profit | B12: ='Data Sheet (2)'!B30 -> 1042.19 | C12: ='Data Sheet (2)'!C30 -> 1254.68 | D12: ='Data Sheet (2)'!D30 -> 2226.3 | E12: ='Data Sheet (2)'!E30 -> 1700.17 | F12: ='Data Sheet (2)'!F30 -> 970.94 | G12: ='Data Sheet (2)'!G30 -> 1070.11 | H12: ='Data Sheet (2)'!H30 -> 1623.25 | I12: ='Data Sheet (2)'!I30 -> 2320.1 | ... K12: ='Data Sheet (2)'!K30 -> 2981.18 | L12: =SUM('Quarters (2)'!H12:K12) -> 3182.55 | M12: =M10-M11*M10 -> 3766.2485 | N12: =N10-N11*N10 -> 2271.3234
A13: EPS | B13: =IF('Data Sheet (2)'!B93>0,B12/'Data Sheet (2)'!B93,0) -> 4.8269649 | C13: =IF('Data Sheet (2)'!C93>0,C12/'Data Sheet (2)'!C93,0) -> 5.1125871 | D13: =IF('Data Sheet (2)'!D93>0,D12/'Data Sheet (2)'!D93,0) -> 9.0573637 | E13: =IF('Data Sheet (2)'!E93>0,E12/'Data Sheet (2)'!E93,0) -> 6.8961223 | F13: =IF('Data Sheet (2)'!F93>0,F12/'Data Sheet (2)'!F93,0) -> 3.9318863 | G13: =IF('Data Sheet (2)'!G93>0,G12/'Data Sheet (2)'!G93,0) -> 4.3254244 | H13: =IF('Data Sheet (2)'!H93>0,H12/'Data Sheet (2)'!H93,0) -> 6.5461548 | I13: =IF('Data Sheet (2)'!I93>0,I12/'Data Sheet (2)'!I93,0) -> 9.3217887 | ... K13: =IF('Data Sheet (2)'!K93>0,K12/'Data Sheet (2)'!K93,0) -> 11.903769 | L13: =IF('Data Sheet (2)'!$B6>0,'Profit & Loss (2)'!L12/'Data Sheet (2)'!$B6,0) -> 12.685333 | M13: =IF('Data Sheet (2)'!$B6>0,'Profit & Loss (2)'!M12/'Data Sheet (2)'!$B6,0) -> 15.011898 | N13: =IF('Data Sheet (2)'!$B6>0,'Profit & Loss (2)'!N12/'Data Sheet (2)'!$B6,0) -> 9.0532725
A14: Price to earning | B14: =IF(B15>0,B15/B13,"") -> 23.826566 | C14: =IF(C15>0,C15/C13,"") -> 28.580442 | D14: =IF(D15>0,D15/D13,"") -> 15.665706 | E14: =IF(E15>0,E15/E13,"") -> 6.9183808 | F14: =IF(F15>0,F15/F13,"") -> 24.377612 | G14: =IF(G15>0,G15/G13,"") -> 18.63401 | H14: =IF(H15>0,H15/H13,"") -> 12.534076 | I14: =IF(I15>0,I15/I13,"") -> 16.976356 | ... K14: =IF(K15>0,K15/K13,"") -> 20.178482 | L14: =IF(L13>0,L15/L13,0) -> 24.6584 | M14: =M25 -> 24.6584 | N14: =N25 -> 17.342142
A15: Price | B15: ='Data Sheet (2)'!B90 -> 115.01 | C15: ='Data Sheet (2)'!C90 -> 146.12 | D15: ='Data Sheet (2)'!D90 -> 141.89 | E15: ='Data Sheet (2)'!E90 -> 47.71 | F15: ='Data Sheet (2)'!F90 -> 95.85 | G15: ='Data Sheet (2)'!G90 -> 80.6 | H15: ='Data Sheet (2)'!H90 -> 82.05 | I15: ='Data Sheet (2)'!I90 -> 158.25 | ... K15: ='Data Sheet (2)'!K90 -> 240.2 | L15: ='Data Sheet (2)'!B8 -> 312.8 | M15: =M13*M14 -> 370.16937 | N15: =N13*N14 -> 157.00314
A17: RATIOS:
A18: Dividend Payout | B18: =IF('Data Sheet (2)'!B30>0, 'Data Sheet (2)'!B31/'Data Sheet (2)'!B30, 0) -> 0.13477389 | C18: =IF('Data Sheet (2)'!C30>0, 'Data Sheet (2)'!C31/'Data Sheet (2)'!C30, 0) -> 0.15906048 | D18: =IF('Data Sheet (2)'!D30>0, 'Data Sheet (2)'!D31/'Data Sheet (2)'!D30, 0) -> 0.089781251 | E18: =IF('Data Sheet (2)'!E30>0, 'Data Sheet (2)'!E31/'Data Sheet (2)'!E30, 0) -> 0.10612468 | F18: =IF('Data Sheet (2)'!F30>0, 'Data Sheet (2)'!F31/'Data Sheet (2)'!F30, 0) -> 0 | G18: =IF('Data Sheet (2)'!G30>0, 'Data Sheet (2)'!G31/'Data Sheet (2)'!G30, 0) -> 0.11559559 | H18: =IF('Data Sheet (2)'!H30>0, 'Data Sheet (2)'!H31/'Data Sheet (2)'!H30, 0) -> 0.30551671 | I18: =IF('Data Sheet (2)'!I30>0, 'Data Sheet (2)'!I31/'Data Sheet (2)'!I30, 0) -> 0.26819534 | ... K18: =IF('Data Sheet (2)'!K30>0, 'Data Sheet (2)'!K31/'Data Sheet (2)'!K30, 0) -> 0.23101926
A19: OPM | B19: =IF(B6>0,B6/B4,0) -> 0.67462651 | C19: =IF(C6>0,C6/C4,0) -> 0.67616684 | D19: =IF(D6>0,D6/D4,0) -> 0.74729984 | E19: =IF(E6>0,E6/E4,0) -> 0.70503867 | F19: =IF(F6>0,F6/F4,0) -> 0.59550433 | G19: =IF(G6>0,G6/G4,0) -> 0.5613427 | H19: =IF(H6>0,H6/H4,0) -> 0.37883827 | I19: =IF(I6>0,I6/I4,0) -> 0.56530409 | ... L19: =IF(L6>0,L6/L4,0) -> 0.61234672
G22: TRENDS: | H22: 10 YEARS | I22: 7 YEARS | J22: 5 YEARS | K22: 3 YEARS | L22: RECENT | M22: BEST | N22: WORST
G23: Sales Growth | H23: =IF(B4=0,"",POWER($K4/B4,1/9)-1) -> 0.085912948 | I23: =IF(D4=0,"",POWER($K4/D4,1/7)-1) -> 0.042735077 | J23: =IF(F4=0,"",POWER($K4/F4,1/5)-1) -> 0.060527953 | K23: =IF(H4=0,"",POWER($K4/H4, 1/3)-1) -> 0.11928784 | L23: =IF(ISERROR(MAX(IF(J4=0,"",(K4-J4)/J4),IF(K4=0,"",(L4-K4)/K4))),"",MAX(IF(J4=0,"",(K4-J4)/J4),IF(K4=0,"",(L4-K4)/K4))) -> 0.12493092 | M23: =MAX(K23:L23) -> 0.12493092 | N23: =MIN(H23:L23) -> 0.042735077
G24: OPM | H24: =IF(SUM(B4:$K$4)=0,"",SUMPRODUCT(B19:$K$19,B4:$K$4)/SUM(B4:$K$4)) -> 0.60989322 | I24: =IF(SUM(E4:$K$4)=0,"",SUMPRODUCT(E19:$K$19,E4:$K$4)/SUM(E4:$K$4)) -> 0.57931343 | J24: =IF(SUM(G4:$K$4)=0,"",SUMPRODUCT(G19:$K$19,G4:$K$4)/SUM(G4:$K$4)) -> 0.55198383 | K24: =IF(SUM(I4:$K$4)=0, "", SUMPRODUCT(I19:$K$19,I4:$K$4)/SUM(I4:$K$4)) -> 0.59565807 | L24: =L19 -> 0.61234672 | M24: =MAX(K24:L24) -> 0.61234672 | N24: =MIN(H24:L24) -> 0.55198383
G25: Price to Earning | H25: =IF(ISERROR(AVERAGEIF(B14:$L14,">0")),"",AVERAGEIF(B14:$L14,">0")) -> 18.800896 | I25: =IF(ISERROR(AVERAGEIF(E14:$L14,">0")),"",AVERAGEIF(E14:$L14,">0")) -> 17.342142 | J25: =IF(ISERROR(AVERAGEIF(G14:$L14,">0")),"",AVERAGEIF(G14:$L14,">0")) -> 17.906858 | K25: =IF(ISERROR(AVERAGEIF(I14:$L14,">0")),"",AVERAGEIF(I14:$L14,">0")) -> 19.068265 | L25: =L14 -> 24.6584 | M25: =MAX(K25:L25) -> 24.6584 | N25: =MIN(H25:L25) -> 17.342142

Sheet Quarters (2)
A1: ='Profit & Loss (2)'!A1 -> L&T FINANCE LTD | E1: =UPDATE | J1: SCREENER.IN
A3: Narration | B3: ='Data Sheet (2)'!B41 -> 45382 | C3: ='Data Sheet (2)'!C41 -> 45473 | D3: ='Data Sheet (2)'!D41 -> 45565 | E3: ='Data Sheet (2)'!E41 -> 45657 | F3: ='Data Sheet (2)'!F41 -> 45747 | G3: ='Data Sheet (2)'!G41 -> 45838 | H3: ='Data Sheet (2)'!H41 -> 45930 | I3: ='Data Sheet (2)'!I41 -> 46022 | ... K3: ='Data Sheet (2)'!K41 -> 46203
A4: Sales | B4: ='Data Sheet (2)'!B42 -> 3670.3 | C4: ='Data Sheet (2)'!C42 -> 3784.4 | D4: ='Data Sheet (2)'!D42 -> 4019.34 | E4: ='Data Sheet (2)'!E42 -> 4097.58 | F4: ='Data Sheet (2)'!F42 -> 4022.92 | G4: ='Data Sheet (2)'!G42 -> 4259.57 | H4: ='Data Sheet (2)'!H42 -> 4335.75 | I4: ='Data Sheet (2)'!I42 -> 4578.27 | ... K4: ='Data Sheet (2)'!K42 -> 5212.92
A5: Expenses | B5: ='Data Sheet (2)'!B43 -> 1619.08 | C5: ='Data Sheet (2)'!C43 -> 1482.49 | D5: ='Data Sheet (2)'!D43 -> 1574.88 | E5: ='Data Sheet (2)'!E43 -> 1675.8 | F5: ='Data Sheet (2)'!F43 -> 1580.89 | G5: ='Data Sheet (2)'!G43 -> 1639.95 | H5: ='Data Sheet (2)'!H43 -> 1661.69 | I5: ='Data Sheet (2)'!I43 -> 1800.09 | ... K5: ='Data Sheet (2)'!K43 -> 1974.28
A6: Operating Profit | B6: ='Data Sheet (2)'!B50 -> 2051.22 | C6: ='Data Sheet (2)'!C50 -> 2301.91 | D6: ='Data Sheet (2)'!D50 -> 2444.46 | E6: ='Data Sheet (2)'!E50 -> 2421.78 | F6: ='Data Sheet (2)'!F50 -> 2442.03 | G6: ='Data Sheet (2)'!G50 -> 2619.62 | H6: ='Data Sheet (2)'!H50 -> 2674.06 | I6: ='Data Sheet (2)'!I50 -> 2778.18 | ... K6: ='Data Sheet (2)'!K50 -> 3238.64
A7: Other Income | B7: ='Data Sheet (2)'!B44 -> 5.55 | C7: ='Data Sheet (2)'!C44 -> 0.21 | D7: ='Data Sheet (2)'!D44 -> 4.68 | E7: ='Data Sheet (2)'!E44 -> 7.55 | F7: ='Data Sheet (2)'!F44 -> 4.3 | G7: ='Data Sheet (2)'!G44 -> 0.03 | H7: ='Data Sheet (2)'!H44 -> 0.04 | I7: ='Data Sheet (2)'!I44 -> -25.29 | ... K7: ='Data Sheet (2)'!K44 -> 30.39
A8: Depreciation | B8: ='Data Sheet (2)'!B45 -> 27.66 | C8: ='Data Sheet (2)'!C45 -> 28.44 | D8: ='Data Sheet (2)'!D45 -> 33.29 | E8: ='Data Sheet (2)'!E45 -> 36.19 | F8: ='Data Sheet (2)'!F45 -> 40.98 | G8: ='Data Sheet (2)'!G45 -> 40.69 | H8: ='Data Sheet (2)'!H45 -> 50.95 | I8: ='Data Sheet (2)'!I45 -> 57.7 | ... K8: ='Data Sheet (2)'!K45 -> 62.68
A9: Interest | B9: ='Data Sheet (2)'!B46 -> 1335.09 | C9: ='Data Sheet (2)'!C46 -> 1351.41 | D9: ='Data Sheet (2)'!D46 -> 1476.28 | E9: ='Data Sheet (2)'!E46 -> 1569.24 | F9: ='Data Sheet (2)'!F46 -> 1599.83 | G9: ='Data Sheet (2)'!G46 -> 1635.74 | H9: ='Data Sheet (2)'!H46 -> 1634.29 | I9: ='Data Sheet (2)'!I46 -> 1703.02 | ... K9: ='Data Sheet (2)'!K46 -> 1970.07
A10: Profit before tax | B10: ='Data Sheet (2)'!B47 -> 694.02 | C10: ='Data Sheet (2)'!C47 -> 922.27 | D10: ='Data Sheet (2)'!D47 -> 939.57 | E10: ='Data Sheet (2)'!E47 -> 823.9 | F10: ='Data Sheet (2)'!F47 -> 805.52 | G10: ='Data Sheet (2)'!G47 -> 943.22 | H10: ='Data Sheet (2)'!H47 -> 988.86 | I10: ='Data Sheet (2)'!I47 -> 992.17 | ... K10: ='Data Sheet (2)'!K47 -> 1236.28
A11: Tax | B11: ='Data Sheet (2)'!B48 -> 141 | C11: ='Data Sheet (2)'!C48 -> 237.02 | D11: ='Data Sheet (2)'!D48 -> 242.89 | E11: ='Data Sheet (2)'!E48 -> 198.25 | F11: ='Data Sheet (2)'!F48 -> 169.68 | G11: ='Data Sheet (2)'!G48 -> 242.38 | H11: ='Data Sheet (2)'!H48 -> 253.98 | I11: ='Data Sheet (2)'!I48 -> 254.18 | ... K11: ='Data Sheet (2)'!K48 -> 320.29
A12: Net profit | B12: ='Data Sheet (2)'!B49 -> 553.88 | C12: ='Data Sheet (2)'!C49 -> 685.51 | D12: ='Data Sheet (2)'!D49 -> 695.58 | E12: ='Data Sheet (2)'!E49 -> 626.4 | F12: ='Data Sheet (2)'!F49 -> 636.17 | G12: ='Data Sheet (2)'!G49 -> 701.1 | H12: ='Data Sheet (2)'!H49 -> 734.84 | I12: ='Data Sheet (2)'!I49 -> 738.61 | ... K12: ='Data Sheet (2)'!K49 -> 902.47
A14: OPM | B14: =IF(B4>0,B6/B4,"") -> 0.55886985 | C14: =IF(C4>0,C6/C4,"") -> 0.60826287 | D14: =IF(D4>0,D6/D4,"") -> 0.60817448 | E14: =IF(E4>0,E6/E4,"") -> 0.5910269 | F14: =IF(F4>0,F6/F4,"") -> 0.60702922 | G14: =IF(G4>0,G6/G4,"") -> 0.61499635 | H14: =IF(H4>0,H6/H4,"") -> 0.61674681 | I14: =IF(I4>0,I6/I4,"") -> 0.60681873 | ... K14: =IF(K4>0,K6/K4,"") -> 0.62127176

Sheet Balance Sheet (2)
A1: ='Profit & Loss (2)'!A1 -> L&T FINANCE LTD | E1: =UPDATE | J1: SCREENER.IN
A3: Narration | B3: ='Data Sheet (2)'!B56 -> 42825 | C3: ='Data Sheet (2)'!C56 -> 43190 | D3: ='Data Sheet (2)'!D56 -> 43555 | E3: ='Data Sheet (2)'!E56 -> 43921 | F3: ='Data Sheet (2)'!F56 -> 44286 | G3: ='Data Sheet (2)'!G56 -> 44651 | H3: ='Data Sheet (2)'!H56 -> 45016 | I3: ='Data Sheet (2)'!I56 -> 45382 | ... K3: ='Data Sheet (2)'!K56 -> 46112
A4: Equity Share Capital | B4: ='Data Sheet (2)'!B57 -> 1755.72 | C4: ='Data Sheet (2)'!C57 -> 1995.68 | D4: ='Data Sheet (2)'!D57 -> 1998.81 | E4: ='Data Sheet (2)'!E57 -> 2004.83 | F4: ='Data Sheet (2)'!F57 -> 2469.45 | G4: ='Data Sheet (2)'!G57 -> 2474.04 | H4: ='Data Sheet (2)'!H57 -> 2479.67 | I4: ='Data Sheet (2)'!I57 -> 2488.94 | ... K4: ='Data Sheet (2)'!K57 -> 2504.39
A5: Reserves | B5: ='Data Sheet (2)'!B58 -> 6138.22 | C5: ='Data Sheet (2)'!C58 -> 9411.06 | D5: ='Data Sheet (2)'!D58 -> 11449.79 | E5: ='Data Sheet (2)'!E58 -> 12687.59 | F5: ='Data Sheet (2)'!F58 -> 16303.75 | G5: ='Data Sheet (2)'!G58 -> 17473.66 | H5: ='Data Sheet (2)'!H58 -> 19048.7 | I5: ='Data Sheet (2)'!I58 -> 20949.5 | ... K5: ='Data Sheet (2)'!K58 -> 25479.14
A6: Borrowings | B6: ='Data Sheet (2)'!B59 -> 61024.45 | C6: ='Data Sheet (2)'!C59 -> 75248.28 | D6: ='Data Sheet (2)'!D59 -> 91506.98 | E6: ='Data Sheet (2)'!E59 -> 93934.07 | F6: ='Data Sheet (2)'!F59 -> 88591.57 | G6: ='Data Sheet (2)'!G59 -> 85236.76 | H6: ='Data Sheet (2)'!H59 -> 83104.9 | I6: ='Data Sheet (2)'!I59 -> 76603.45 | ... K6: ='Data Sheet (2)'!K59 -> 110297.66
A7: Other Liabilities | B7: ='Data Sheet (2)'!B60 -> 3592.81 | C7: ='Data Sheet (2)'!C60 -> 1117.4 | D7: ='Data Sheet (2)'!D60 -> 1094.33 | E7: ='Data Sheet (2)'!E60 -> 902.07 | F7: ='Data Sheet (2)'!F60 -> 1581.99 | G7: ='Data Sheet (2)'!G60 -> 1695.92 | H7: ='Data Sheet (2)'!H60 -> 1705.53 | I7: ='Data Sheet (2)'!I60 -> 2651.95 | ... K7: ='Data Sheet (2)'!K60 -> 3902.54
A8: Total | B8: ='Data Sheet (2)'!B61 -> 72511.2 | C8: ='Data Sheet (2)'!C61 -> 87772.42 | D8: ='Data Sheet (2)'!D61 -> 106049.91 | E8: ='Data Sheet (2)'!E61 -> 109528.56 | F8: ='Data Sheet (2)'!F61 -> 108946.76 | G8: ='Data Sheet (2)'!G61 -> 106880.38 | H8: ='Data Sheet (2)'!H61 -> 106338.8 | I8: ='Data Sheet (2)'!I61 -> 102693.84 | ... K8: ='Data Sheet (2)'!K61 -> 142183.73
A10: Net Block | B10: ='Data Sheet (2)'!B62 -> 1229.87 | C10: ='Data Sheet (2)'!C62 -> 1150.72 | D10: ='Data Sheet (2)'!D62 -> 1127.3 | E10: ='Data Sheet (2)'!E62 -> 1100.07 | F10: ='Data Sheet (2)'!F62 -> 1138.29 | G10: ='Data Sheet (2)'!G62 -> 508.81 | H10: ='Data Sheet (2)'!H62 -> 552.52 | I10: ='Data Sheet (2)'!I62 -> 519.35 | ... K10: ='Data Sheet (2)'!K62 -> 1307.63
A11: Capital Work in Progress | B11: ='Data Sheet (2)'!B63 -> 27.89 | C11: ='Data Sheet (2)'!C63 -> 19.34 | D11: ='Data Sheet (2)'!D63 -> 38.65 | E11: ='Data Sheet (2)'!E63 -> 62.04 | F11: ='Data Sheet (2)'!F63 -> 23.84 | G11: ='Data Sheet (2)'!G63 -> 21.81 | H11: ='Data Sheet (2)'!H63 -> 4.81 | I11: ='Data Sheet (2)'!I63 -> 35.62 | ... K11: ='Data Sheet (2)'!K63 -> 61.87
A12: Investments | B12: ='Data Sheet (2)'!B64 -> 6011.53 | C12: ='Data Sheet (2)'!C64 -> 5301.49 | D12: ='Data Sheet (2)'!D64 -> 8640.81 | E12: ='Data Sheet (2)'!E64 -> 5979.27 | F12: ='Data Sheet (2)'!F64 -> 8872.13 | G12: ='Data Sheet (2)'!G64 -> 11916.94 | H12: ='Data Sheet (2)'!H64 -> 14366.2 | I12: ='Data Sheet (2)'!I64 -> 12384.89 | ... K12: ='Data Sheet (2)'!K64 -> 10563.81
A13: Other Assets | B13: ='Data Sheet (2)'!B65 -> 65241.91 | C13: ='Data Sheet (2)'!C65 -> 81300.87 | D13: ='Data Sheet (2)'!D65 -> 96243.15 | E13: ='Data Sheet (2)'!E65 -> 102387.18 | F13: ='Data Sheet (2)'!F65 -> 98912.5 | G13: ='Data Sheet (2)'!G65 -> 94432.82 | H13: ='Data Sheet (2)'!H65 -> 91415.27 | I13: ='Data Sheet (2)'!I65 -> 89753.98 | ... K13: ='Data Sheet (2)'!K65 -> 130250.42
A14: Total | B14: ='Data Sheet (2)'!B66 -> 72511.2 | C14: ='Data Sheet (2)'!C66 -> 87772.42 | D14: ='Data Sheet (2)'!D66 -> 106049.91 | E14: ='Data Sheet (2)'!E66 -> 109528.56 | F14: ='Data Sheet (2)'!F66 -> 108946.76 | G14: ='Data Sheet (2)'!G66 -> 106880.38 | H14: ='Data Sheet (2)'!H66 -> 106338.8 | I14: ='Data Sheet (2)'!I66 -> 102693.84 | ... K14: ='Data Sheet (2)'!K66 -> 142183.73
A16: Working Capital | B16: =B13-B7 -> 61649.1 | C16: =C13-C7 -> 80183.47 | D16: =D13-D7 -> 95148.82 | E16: =E13-E7 -> 101485.11 | F16: =F13-F7 -> 97330.51 | G16: =G13-G7 -> 92736.9 | H16: =H13-H7 -> 89709.74 | I16: =I13-I7 -> 87102.03 | ... K16: =K13-K7 -> 126347.88
A17: Debtors | B17: ='Data Sheet (2)'!B67 -> 78.85 | C17: ='Data Sheet (2)'!C67 -> 126.44 | D17: ='Data Sheet (2)'!D67 -> 106.37 | E17: ='Data Sheet (2)'!E67 -> 64.74 | F17: ='Data Sheet (2)'!F67 -> 47.31 | G17: ='Data Sheet (2)'!G67 -> 15.92 | H17: ='Data Sheet (2)'!H67 -> 5.88 | I17: ='Data Sheet (2)'!I67 -> 247.28 | ... K17: ='Data Sheet (2)'!K67 -> 102.47
A18: Inventory | B18: ='Data Sheet (2)'!B68 -> 0 | C18: ='Data Sheet (2)'!C68 -> 0 | D18: ='Data Sheet (2)'!D68 -> 0 | E18: ='Data Sheet (2)'!E68 -> 0 | F18: ='Data Sheet (2)'!F68 -> 0 | G18: ='Data Sheet (2)'!G68 -> 0 | H18: ='Data Sheet (2)'!H68 -> 0 | I18: ='Data Sheet (2)'!I68 -> 0 | ... K18: ='Data Sheet (2)'!K68 -> 0
A20: Debtor Days | B20: =IF('Profit & Loss (2)'!B4>0,'Balance Sheet (2)'!B17/('Profit & Loss (2)'!B4/365),0) -> 3.3733787 | C20: =IF('Profit & Loss (2)'!C4>0,'Balance Sheet (2)'!C17/('Profit & Loss (2)'!C4/365),0) -> 4.5181237 | D20: =IF('Profit & Loss (2)'!D4>0,'Balance Sheet (2)'!D17/('Profit & Loss (2)'!D4/365),0) -> 2.9049946 | E20: =IF('Profit & Loss (2)'!E4>0,'Balance Sheet (2)'!E17/('Profit & Loss (2)'!E4/365),0) -> 1.6754041 | F20: =IF('Profit & Loss (2)'!F4>0,'Balance Sheet (2)'!F17/('Profit & Loss (2)'!F4/365),0) -> 1.2932183 | G20: =IF('Profit & Loss (2)'!G4>0,'Balance Sheet (2)'!G17/('Profit & Loss (2)'!G4/365),0) -> 0.48708685 | H20: =IF('Profit & Loss (2)'!H4>0,'Balance Sheet (2)'!H17/('Profit & Loss (2)'!H4/365),0) -> 0.16800066 | I20: =IF('Profit & Loss (2)'!I4>0,'Balance Sheet (2)'!I17/('Profit & Loss (2)'!I4/365),0) -> 6.3330786 | ... K20: =IF('Profit & Loss (2)'!K4>0,'Balance Sheet (2)'!K17/('Profit & Loss (2)'!K4/365),0) -> 2.0878776
A21: Inventory Turnover | B21: =IF('Balance Sheet (2)'!B18>0,'Profit & Loss (2)'!B4/'Balance Sheet (2)'!B18,0) -> 0 | C21: =IF('Balance Sheet (2)'!C18>0,'Profit & Loss (2)'!C4/'Balance Sheet (2)'!C18,0) -> 0 | D21: =IF('Balance Sheet (2)'!D18>0,'Profit & Loss (2)'!D4/'Balance Sheet (2)'!D18,0) -> 0 | E21: =IF('Balance Sheet (2)'!E18>0,'Profit & Loss (2)'!E4/'Balance Sheet (2)'!E18,0) -> 0 | F21: =IF('Balance Sheet (2)'!F18>0,'Profit & Loss (2)'!F4/'Balance Sheet (2)'!F18,0) -> 0 | G21: =IF('Balance Sheet (2)'!G18>0,'Profit & Loss (2)'!G4/'Balance Sheet (2)'!G18,0) -> 0 | H21: =IF('Balance Sheet (2)'!H18>0,'Profit & Loss (2)'!H4/'Balance Sheet (2)'!H18,0) -> 0 | I21: =IF('Balance Sheet (2)'!I18>0,'Profit & Loss (2)'!I4/'Balance Sheet (2)'!I18,0) -> 0 | ... K21: =IF('Balance Sheet (2)'!K18>0,'Profit & Loss (2)'!K4/'Balance Sheet (2)'!K18,0) -> 0
A23: Return on Equity | B23: =IF(SUM('Balance Sheet (2)'!B4:B5)>0,'Profit & Loss (2)'!B12/SUM('Balance Sheet (2)'!B4:B5),"") -> 0.13202406 | C23: =IF(SUM('Balance Sheet (2)'!C4:C5)>0,'Profit & Loss (2)'!C12/SUM('Balance Sheet (2)'!C4:C5),"") -> 0.10999462 | D23: =IF(SUM('Balance Sheet (2)'!D4:D5)>0,'Profit & Loss (2)'!D12/SUM('Balance Sheet (2)'!D4:D5),"") -> 0.16554139 | E23: =IF(SUM('Balance Sheet (2)'!E4:E5)>0,'Profit & Loss (2)'!E12/SUM('Balance Sheet (2)'!E4:E5),"") -> 0.11571749 | F23: =IF(SUM('Balance Sheet (2)'!F4:F5)>0,'Profit & Loss (2)'!F12/SUM('Balance Sheet (2)'!F4:F5),"") -> 0.051719472 | G23: =IF(SUM('Balance Sheet (2)'!G4:G5)>0,'Profit & Loss (2)'!G12/SUM('Balance Sheet (2)'!G4:G5),"") -> 0.053645784 | H23: =IF(SUM('Balance Sheet (2)'!H4:H5)>0,'Profit & Loss (2)'!H12/SUM('Balance Sheet (2)'!H4:H5),"") -> 0.075400506 | I23: =IF(SUM('Balance Sheet (2)'!I4:I5)>0,'Profit & Loss (2)'!I12/SUM('Balance Sheet (2)'!I4:I5),"") -> 0.098986963 | ... K23: =IF(SUM('Balance Sheet (2)'!K4:K5)>0,'Profit & Loss (2)'!K12/SUM('Balance Sheet (2)'!K4:K5),"") -> 0.10653338
A24: Return on Capital Emp | C24: =IF((B4+B5+B6+C4+C5+C6)>0,('Profit & Loss (2)'!C10+'Profit & Loss (2)'!C9)*2/(B4+B5+B6+C4+C5+C6),"") -> 0.088749228 | D24: =IF((C4+C5+C6+D4+D5+D6)>0,('Profit & Loss (2)'!D10+'Profit & Loss (2)'!D9)*2/(C4+C5+C6+D4+D5+D6),"") -> 0.10369218 | E24: =IF((D4+D5+D6+E4+E5+E6)>0,('Profit & Loss (2)'!E10+'Profit & Loss (2)'!E9)*2/(D4+D5+D6+E4+E5+E6),"") -> 0.095816283 | F24: =IF((E4+E5+E6+F4+F5+F6)>0,('Profit & Loss (2)'!F10+'Profit & Loss (2)'!F9)*2/(E4+E5+E6+F4+F5+F6),"") -> 0.080578631 | G24: =IF((F4+F5+F6+G4+G5+G6)>0,('Profit & Loss (2)'!G10+'Profit & Loss (2)'!G9)*2/(F4+F5+F6+G4+G5+G6),"") -> 0.067634872 | H24: =IF((G4+G5+G6+H4+H5+H6)>0,('Profit & Loss (2)'!H10+'Profit & Loss (2)'!H9)*2/(G4+G5+G6+H4+H5+H6),"") -> 0.07168622 | I24: =IF((H4+H5+H6+I4+I5+I6)>0,('Profit & Loss (2)'!I10+'Profit & Loss (2)'!I9)*2/(H4+H5+H6+I4+I5+I6),"") -> 0.0822346 | J24: =IF((I4+I5+I6+J4+J5+J6)>0,('Profit & Loss (2)'!J10+'Profit & Loss (2)'!J9)*2/(I4+I5+I6+J4+J5+J6),"") -> 0.087145703 | K24: =IF((J4+J5+J6+K4+K5+K6)>0,('Profit & Loss (2)'!K10+'Profit & Loss (2)'!K9)*2/(J4+J5+J6+K4+K5+K6),"") -> 0.083772436

Sheet Cash Flow (2)
A1: ='Balance Sheet (2)'!A1 -> L&T FINANCE LTD | E1: =UPDATE | J1: SCREENER.IN
A3: Narration | B3: ='Data Sheet (2)'!B81 -> 42825 | C3: ='Data Sheet (2)'!C81 -> 43190 | D3: ='Data Sheet (2)'!D81 -> 43555 | E3: ='Data Sheet (2)'!E81 -> 43921 | F3: ='Data Sheet (2)'!F81 -> 44286 | G3: ='Data Sheet (2)'!G81 -> 44651 | H3: ='Data Sheet (2)'!H81 -> 45016 | I3: ='Data Sheet (2)'!I81 -> 45382 | ... K3: ='Data Sheet (2)'!K81 -> 46112
A4: Cash from Operating Activity | B4: ='Data Sheet (2)'!B82 -> -5779.41 | C4: ='Data Sheet (2)'!C82 -> -15639.71 | D4: ='Data Sheet (2)'!D82 -> -11643.45 | E4: ='Data Sheet (2)'!E82 -> 2161.76 | F4: ='Data Sheet (2)'!F82 -> 5464.3 | G4: ='Data Sheet (2)'!G82 -> 6078.06 | H4: ='Data Sheet (2)'!H82 -> 7490.47 | I4: ='Data Sheet (2)'!I82 -> 685.64 | ... K4: ='Data Sheet (2)'!K82 -> -14189.24
A5: Cash from Investing Activity | B5: ='Data Sheet (2)'!B83 -> -2117.54 | C5: ='Data Sheet (2)'!C83 -> 1548.8 | D5: ='Data Sheet (2)'!D83 -> -3587.48 | E5: ='Data Sheet (2)'!E83 -> 159.75 | F5: ='Data Sheet (2)'!F83 -> -2024.52 | G5: ='Data Sheet (2)'!G83 -> -5086.86 | H5: ='Data Sheet (2)'!H83 -> -1633.96 | I5: ='Data Sheet (2)'!I83 -> 848.62 | ... K5: ='Data Sheet (2)'!K83 -> 366.9
A6: Cash from Financing Activity | B6: ='Data Sheet (2)'!B84 -> 7952.1 | C6: ='Data Sheet (2)'!C84 -> 14677.8 | D6: ='Data Sheet (2)'!D84 -> 16008.19 | E6: ='Data Sheet (2)'!E84 -> 1450.53 | F6: ='Data Sheet (2)'!F84 -> -2090.68 | G6: ='Data Sheet (2)'!G84 -> -3023.01 | H6: ='Data Sheet (2)'!H84 -> -1663.81 | I6: ='Data Sheet (2)'!I84 -> -7049.59 | ... K6: ='Data Sheet (2)'!K84 -> 15415.06
A7: Net Cash Flow | B7: ='Data Sheet (2)'!B85 -> 55.15 | C7: ='Data Sheet (2)'!C85 -> 586.89 | D7: ='Data Sheet (2)'!D85 -> 777.26 | E7: ='Data Sheet (2)'!E85 -> 3772.04 | F7: ='Data Sheet (2)'!F85 -> 1349.1 | G7: ='Data Sheet (2)'!G85 -> -2031.81 | H7: ='Data Sheet (2)'!H85 -> 4192.7 | I7: ='Data Sheet (2)'!I85 -> -5515.33 | ... K7: ='Data Sheet (2)'!K85 -> 1592.72

Sheet Customization (2)
A1: How to use it?
A3: You can customize this workbook as you want.
B4: You can add custom formating, add conditional formating, add your own formulas… do ANYTHING.
B5: Please don't edit the "Data Sheet" only.
A7: After customization, you can upload this back on Screener.
B8: Upload on: | C8: https://www.screener.in/excel/
A10: Download your customized workbooks now onwards.
B11: Now whenever you will "Export to excel" from Screener, it will export your customized file.
A14: TESTING:
B15: This is a testing feature currently.
B16: You can report any formula errors on the worksheet at: support@screener.in

Sheet Data Sheet (2)
A1: COMPANY NAME | B1: L&T FINANCE LTD | E1: =IF(B2<>B3, "A NEW VERSION OF THE WORKSHEET IS AVAILABLE", "")
A2: LATEST VERSION | B2: 2.1 | E2: PLEASE DO NOT MAKE ANY CHANGES TO THIS SHEET
A3: CURRENT VERSION | B3: 2.1
A5: META
A6: Number of shares | B6: =IF(B9>0, B9/B8, 0) -> 250.88424
A7: Face Value | B7: 10
A8: Current Price | B8: 312.8
A9: Market Capitalization | B9: 78476.59
A15: PROFIT & LOSS
A16: Report Date | B16: 42825 | C16: 43190 | D16: 43555 | E16: 43921 | F16: 44286 | G16: 44651 | H16: 45016 | I16: 45382 | J16: 45747 | K16: 46112
A17: Sales | B17: 8531.58 | C17: 10214.55 | D17: 13364.93 | E17: 14104.12 | F17: 13352.85 | G17: 11929.7 | H17: 12774.95 | I17: 14251.71 | J17: 15924.24 | K17: 17913.67
A18: Raw Material Cost
A19: Change in Inventory
A20: Power and Fuel | B20: 5.87 | C20: 7.76 | D20: 8.61 | E20: 8.08 | F20: 6.29 | G20: 6.49 | H20: 6.13
A21: Other Mfr. Exp | B21: 59.24 | C21: 510.99 | D21: 1243.16 | E21: 429.58 | F21: 736.46 | G21: 1454.35 | H21: 1047.06 | I21: 1552.94 | J21: 307 | K21: 606.97
A22: Employee Cost | B22: 499.18 | C22: 413.57 | D22: 829.1 | E22: 1066.44 | F22: 941.12 | G22: 1099.1 | H22: 1409.89 | I22: 1808.9 | J22: 2217.66 | K22: 2456.63
A23: Selling and admin | B23: 400.93 | C23: 368.85 | D23: 570.03 | E23: 606.01 | F23: 714.18 | G23: 945.62 | H23: 1197.63 | I23: 1487.64 | J23: 1537.44 | K23: 1615.61
A24: Other Expenses | B24: 1810.73 | C24: 2006.64 | D24: 726.42 | E24: 2050.06 | F24: 3003.12 | G24: 1727.49 | H24: 4274.6 | I24: 1345.68 | J24: 2241.56 | K24: 2266.62
A25: Other Income | B25: 25.93 | C25: 48.7 | D25: -3.73 | E25: 369.96 | F25: 836.12 | G25: 593.86 | H25: 2792.12 | I25: 473.91 | J25: 16.26 | K25: -26.16
A26: Depreciation | B26: 67.3 | C26: 51.93 | D26: 49.62 | E26: 81.59 | F26: 85.66 | G26: 102.64 | H26: 111.24 | I26: 114.77 | J26: 138.9 | K26: 209.69
A27: Interest | B27: 4635.36 | C27: 5457.75 | D27: 6882.28 | E27: 7552.24 | F27: 7230.15 | G27: 5765.01 | H27: 5811.67 | I27: 5386.66 | J27: 6006.68 | K27: 6733.82
A28: Profit before tax | B28: 1078.9 | C28: 1445.76 | D28: 3051.98 | E28: 2680.08 | F28: 1471.99 | G28: 1422.86 | H28: 1708.85 | I28: 3029.03 | J28: 3491.26 | K28: 3998.17
A29: Tax | B29: 36.44 | C29: 168.24 | D29: 819.95 | E29: 979.82 | F29: 523.11 | G29: 373.62 | H29: 172.37 | I29: 711.9 | J29: 847.84 | K29: 1015.3
A30: Net profit | B30: 1042.19 | C30: 1254.68 | D30: 2226.3 | E30: 1700.17 | F30: 970.94 | G30: 1070.11 | H30: 1623.25 | I30: 2320.1 | J30: 2643.66 | K30: 2981.18
A31: Dividend Amount | B31: 140.46 | C31: 199.57 | D31: 199.88 | E31: 180.43 | G31: 123.7 | H31: 495.93 | I31: 622.24 | J31: 686.09 | K31: 688.71
A40: Quarters
A41: Report Date | B41: 45382 | C41: 45473 | D41: 45565 | E41: 45657 | F41: 45747 | G41: 45838 | H41: 45930 | I41: 46022 | J41: 46112 | K41: 46203
A42: Sales | B42: 3670.3 | C42: 3784.4 | D42: 4019.34 | E42: 4097.58 | F42: 4022.92 | G42: 4259.57 | H42: 4335.75 | I42: 4578.27 | J42: 4771.03 | K42: 5212.92
A43: Expenses | B43: 1619.08 | C43: 1482.49 | D43: 1574.88 | E43: 1675.8 | F43: 1580.89 | G43: 1639.95 | H43: 1661.69 | I43: 1800.09 | J43: 1889.8 | K43: 1974.28
A44: Other Income | B44: 5.55 | C44: 0.21 | D44: 4.68 | E44: 7.55 | F44: 4.3 | G44: 0.03 | H44: 0.04 | I44: -25.29 | J44: 0.07 | K44: 30.39
A45: Depreciation | B45: 27.66 | C45: 28.44 | D45: 33.29 | E45: 36.19 | F45: 40.98 | G45: 40.69 | H45: 50.95 | I45: 57.7 | J45: 60.35 | K45: 62.68
A46: Interest | B46: 1335.09 | C46: 1351.41 | D46: 1476.28 | E46: 1569.24 | F46: 1599.83 | G46: 1635.74 | H46: 1634.29 | I46: 1703.02 | J46: 1747.03 | K46: 1970.07
A47: Profit before tax | B47: 694.02 | C47: 922.27 | D47: 939.57 | E47: 823.9 | F47: 805.52 | G47: 943.22 | H47: 988.86 | I47: 992.17 | J47: 1073.92 | K47: 1236.28
A48: Tax | B48: 141 | C48: 237.02 | D48: 242.89 | E48: 198.25 | F48: 169.68 | G48: 242.38 | H48: 253.98 | I48: 254.18 | J48: 264.76 | K48: 320.29
A49: Net profit | B49: 553.88 | C49: 685.51 | D49: 695.58 | E49: 626.4 | F49: 636.17 | G49: 701.1 | H49: 734.84 | I49: 738.61 | J49: 806.63 | K49: 902.47
A50: Operating Profit | B50: 2051.22 | C50: 2301.91 | D50: 2444.46 | E50: 2421.78 | F50: 2442.03 | G50: 2619.62 | H50: 2674.06 | I50: 2778.18 | J50: 2881.23 | K50: 3238.64
A55: BALANCE SHEET
A56: Report Date | B56: 42825 | C56: 43190 | D56: 43555 | E56: 43921 | F56: 44286 | G56: 44651 | H56: 45016 | I56: 45382 | J56: 45747 | K56: 46112
A57: Equity Share Capital | B57: 1755.72 | C57: 1995.68 | D57: 1998.81 | E57: 2004.83 | F57: 2469.45 | G57: 2474.04 | H57: 2479.67 | I57: 2488.94 | J57: 2494.87 | K57: 2504.39
A58: Reserves | B58: 6138.22 | C58: 9411.06 | D58: 11449.79 | E58: 12687.59 | F58: 16303.75 | G58: 17473.66 | H58: 19048.7 | I58: 20949.5 | J58: 23069.19 | K58: 25479.14
...

Sheet Profit & Loss (3)
A1: ='Data Sheet (3)'!B1 -> MUTHOOT FINANCE LTD | H1: =UPDATE | M1: SCREENER.IN
